{
  'robot_description': '<?xml version="1.0" ?>
<!-- =================================================================================== -->
<!-- |    This document was autogenerated by xacro from /home/hayden/cmu/kantor_lab/ros2_ws/install/xarm_description/share/xarm_description/urdf/xarm_device.urdf.xacro | -->
<!-- |    EDITING THIS FILE BY HAND IS NOT RECOMMENDED                                 | -->
<!-- =================================================================================== -->
<robot name="UF_ROBOT"><!-- Insert at the beginning of xarm_device_macro.xacro --><material name="Black"><color rgba="0.0 0.0 0.0 1.0"/></material><material name="Red"><color rgba="0.8 0.0 0.0 1.0"/></material><material name="White"><color rgba="1.0 1.0 1.0 1.0"/></material><material name="Silver"><color rgba="0.753 0.753 0.753 1.0"/></material><link name="world"/><joint name="world_joint" type="fixed"><parent link="world"/><child link="link_base"/><origin rpy="0 0 0" xyz="0 0 0"/></joint><ros2_control name="uf_robot_hardware/UFRobotFakeSystemHardware" type="system"><hardware><plugin>uf_robot_hardware/UFRobotFakeSystemHardware</plugin></hardware><joint name="joint1"><command_interface name="position"><param name="min">-6.283185307179586</param><param name="max">6.283185307179586</param></command_interface><command_interface name="velocity"><param name="min">-3.14</param><param name="max">3.14</param></command_interface><state_interface name="position"/><state_interface name="velocity"/><!-- <state_interface name="effort"/> --></joint><joint name="joint2"><command_interface name="position"><param name="min">-2.059</param><param name="max">2.0944</param></command_interface><command_interface name="velocity"><param name="min">-3.14</param><param name="max">3.14</param></command_interface><state_interface name="position"/><state_interface name="velocity"/><!-- <state_interface name="effort"/> --></joint><joint name="joint3"><command_interface name="position"><param name="min">-6.283185307179586</param><param name="max">6.283185307179586</param></command_interface><command_interface name="velocity"><param name="min">-3.14</param><param name="max">3.14</param></command_interface><state_interface name="position"/><state_interface name="velocity"/><!-- <state_interface name="effort"/> --></joint><joint name="joint4"><command_interface name="position"><param name="min">-0.19198</param><param name="max">3.927</param></command_interface><command_interface name="velocity"><param name="min">-3.14</param><param name="max">3.14</param></command_interface><state_interface name="position"/><state_interface name="velocity"/><!-- <state_interface name="effort"/> --></joint><joint name="joint5"><command_interface name="position"><param name="min">-6.283185307179586</param><param name="max">6.283185307179586</param></command_interface><command_interface name="velocity"><param name="min">-3.14</param><param name="max">3.14</param></command_interface><state_interface name="position"/><state_interface name="velocity"/><!-- <state_interface name="effort"/> --></joint><joint name="joint6"><command_interface name="position"><param name="min">-1.69297</param><param name="max">3.141592653589793</param></command_interface><command_interface name="velocity"><param name="min">-3.14</param><param name="max">3.14</param></command_interface><state_interface name="position"/><state_interface name="velocity"/><!-- <state_interface name="effort"/> --></joint><joint name="joint7"><command_interface name="position"><param name="min">-6.283185307179586</param><param name="max">6.283185307179586</param></command_interface><command_interface name="velocity"><param name="min">-3.14</param><param name="max">3.14</param></command_interface><state_interface name="position"/><state_interface name="velocity"/><!-- <state_interface name="effort"/> --></joint></ros2_control><link name="link_base"><inertial><origin rpy="0 0 0" xyz="-0.021131 -0.0016302 0.056488"/><mass value="0.88556"/><inertia ixx="0.0030595" ixy="0.00012259" ixz="-0.00062705" iyy="0.0037783" iyz="0.00027023" izz="0.0020125"/></inertial><visual><geometry><mesh filename="package://xarm_description/meshes/xarm7/visual/link_base.stl"/></geometry><origin rpy="0 0 0" xyz="0 0 0"/><material name="White"/></visual><collision><geometry><mesh filename="package://xarm_description/meshes/xarm7/visual/link_base.stl"/></geometry><origin rpy="0 0 0" xyz="0 0 0"/></collision></link><link name="link1"><inertial><origin rpy="0 0 0" xyz="-0.0002 0.02905 -0.01233"/><mass value="2.382"/><inertia ixx="0.0056905" ixy="-1.579e-05" ixz="5.125e-06" iyy="0.0049566" iyz="-0.000873378" izz="0.003316654"/></inertial><visual><geometry><mesh filename="package://xarm_description/meshes/xarm7/visual/link1.stl"/></geometry><origin rpy="0 0 0" xyz="0 0 0"/><material name="White"/></visual><collision><geometry><mesh filename="package://xarm_description/meshes/xarm7/visual/link1.stl"/></geometry><origin rpy="0 0 0" xyz="0 0 0"/></collision></link><joint name="joint1" type="revolute"><origin rpy="0 0 0" xyz="0 0 0.267"/><parent link="link_base"/><child link="link1"/><axis xyz="0 0 1"/><limit effort="50" lower="-6.283185307179586" upper="6.283185307179586" velocity="3.14"/><dynamics damping="10" friction="1"/></joint><link name="link2"><inertial><origin rpy="0 0 0" xyz="0.00022 -0.12856 0.01735"/><mass value="1.869"/><inertia ixx="0.0095989" ixy="1.541e-06" ixz="5.56e-06" iyy="0.00382472" iyz="-0.00317156" izz="0.007565669"/></inertial><visual><geometry><mesh filename="package://xarm_description/meshes/xarm7/visual/link2.stl"/></geometry><origin rpy="0 0 0" xyz="0 0 0"/><material name="White"/></visual><collision><geometry><mesh filename="package://xarm_description/meshes/xarm7/visual/link2.stl"/></geometry><origin rpy="0 0 0" xyz="0 0 0"/></collision></link><joint name="joint2" type="revolute"><origin rpy="-1.5708 0 0" xyz="0 0 0"/><parent link="link1"/><child link="link2"/><axis xyz="0 0 1"/><limit effort="50" lower="-2.059" upper="2.0944" velocity="3.14"/><dynamics damping="10" friction="1"/></joint><link name="link3"><inertial><origin rpy="0 0 0" xyz="0.0466 -0.02463 -0.00768"/><mass value="1.6383"/><inertia ixx="0.00310955" ixy="0.00030837" ixz="-0.00058453" iyy="0.00264483" iyz="0.000338893" izz="0.0026624"/></inertial><visual><geometry><mesh filename="package://xarm_description/meshes/xarm7/visual/link3.stl"/></geometry><origin rpy="0 0 0" xyz="0 0 0"/><material name="White"/></visual><collision><geometry><mesh filename="package://xarm_description/meshes/xarm7/visual/link3.stl"/></geometry><origin rpy="0 0 0" xyz="0 0 0"/></collision></link><joint name="joint3" type="revolute"><origin rpy="1.5708 0 0" xyz="0 -0.293 0"/><parent link="link2"/><child link="link3"/><axis xyz="0 0 1"/><limit effort="30" lower="-6.283185307179586" upper="6.283185307179586" velocity="3.14"/><dynamics damping="5" friction="1"/></joint><link name="link4"><inertial><origin rpy="0 0 0" xyz="0.07047 -0.11575 0.012"/><mass value="1.7269"/><inertia ixx="0.005889" ixy="0.00137112" ixz="0.00088143" iyy="0.00359703" iyz="-0.001762155" izz="0.00543244"/></inertial><visual><geometry><mesh filename="package://xarm_description/meshes/xarm7/visual/link4.stl"/></geometry><origin rpy="0 0 0" xyz="0 0 0"/><material name="White"/></visual><collision><geometry><mesh filename="package://xarm_description/meshes/xarm7/visual/link4.stl"/></geometry><origin rpy="0 0 0" xyz="0 0 0"/></collision></link><joint name="joint4" type="revolute"><origin rpy="1.5708 0 0" xyz="0.0525 0 0"/><parent link="link3"/><child link="link4"/><axis xyz="0 0 1"/><limit effort="30" lower="-0.19198" upper="3.927" velocity="3.14"/><dynamics damping="5" friction="1"/></joint><link name="link5"><inertial><origin rpy="0 0 0" xyz="-0.00032 0.01604 -0.026"/><mass value="1.3203"/><inertia ixx="0.00534665" ixy="1.5117e-05" ixz="-3.69e-07" iyy="0.0049779" iyz="-0.00022132" izz="0.0013624"/></inertial><visual><geometry><mesh filename="package://xarm_description/meshes/xarm7/visual/link5.stl"/></geometry><origin rpy="0 0 0" xyz="0 0 0"/><material name="White"/></visual><collision><geometry><mesh filename="package://xarm_description/meshes/xarm7/visual/link5.stl"/></geometry><origin rpy="0 0 0" xyz="0 0 0"/></collision></link><joint name="joint5" type="revolute"><origin rpy="1.5708 0 0" xyz="0.0775 -0.3425 0"/><parent link="link4"/><child link="link5"/><axis xyz="0 0 1"/><limit effort="30" lower="-6.283185307179586" upper="6.283185307179586" velocity="3.14"/><dynamics damping="5" friction="1"/></joint><link name="link6"><inertial><origin rpy="0 0 0" xyz="0.06469 0.03278 0.02141"/><mass value="1.325"/><inertia ixx="0.0014745" ixy="-0.000488" ixz="0.0002953" iyy="0.0019037" iyz="0.00014749" izz="0.0023652"/></inertial><visual><geometry><mesh filename="package://xarm_description/meshes/xarm7/visual/link6.stl"/></geometry><origin rpy="0 0 0" xyz="0 0 0"/><material name="White"/></visual><collision><geometry><mesh filename="package://xarm_description/meshes/xarm7/visual/link6.stl"/></geometry><origin rpy="0 0 0" xyz="0 0 0"/></collision></link><joint name="joint6" type="revolute"><origin rpy="1.5708 0 0" xyz="0 0 0"/><parent link="link5"/><child link="link6"/><axis xyz="0 0 1"/><limit effort="20" lower="-1.69297" upper="3.141592653589793" velocity="3.14"/><dynamics damping="2" friction="1"/></joint><link name="link7"><inertial><origin rpy="0 0 0" xyz="0 -0.00677 -0.01098"/><mass value="0.17"/><inertia ixx="9.3e-05" ixy="-0.0" ixz="-0.0" iyy="5.87e-05" iyz="-3.6e-06" izz="0.000132"/></inertial><visual><geometry><mesh filename="package://xarm_description/meshes/xarm7/visual/link7.stl"/></geometry><origin rpy="0 0 0" xyz="0 0 0"/><material name="Silver"/></visual><collision><geometry><mesh filename="package://xarm_description/meshes/end_tool/collision/end_tool.stl"/></geometry><origin rpy="0 0 0" xyz="0 0 0"/></collision></link><joint name="joint7" type="revolute"><origin rpy="-1.5708 0 0" xyz="0.076 0.097 0"/><parent link="link6"/><child link="link7"/><axis xyz="0 0 1"/><limit effort="20" lower="-6.283185307179586" upper="6.283185307179586" velocity="3.14"/><dynamics damping="2" friction="1"/></joint><!-- <link name="${prefix}link_eef" />\n    <joint name="${prefix}joint_eef" type="fixed">\n      <origin xyz="0 0 0" rpy="0 0 0" />\n      <parent link="${prefix}link7" />\n      <child link="${prefix}link_eef" />\n    </joint> --><transmission name="tran1"><type>transmission_interface/SimpleTransmission</type><joint name="joint1"><hardwareInterface>hardware_interface/PositionJointInterface</hardwareInterface></joint><actuator name="motor1"><hardwareInterface>hardware_interface/PositionJointInterface</hardwareInterface><mechanicalReduction>100</mechanicalReduction></actuator></transmission><transmission name="tran2"><type>transmission_interface/SimpleTransmission</type><joint name="joint2"><hardwareInterface>hardware_interface/PositionJointInterface</hardwareInterface></joint><actuator name="motor2"><hardwareInterface>hardware_interface/PositionJointInterface</hardwareInterface><mechanicalReduction>100</mechanicalReduction></actuator></transmission><transmission name="tran3"><type>transmission_interface/SimpleTransmission</type><joint name="joint3"><hardwareInterface>hardware_interface/PositionJointInterface</hardwareInterface></joint><actuator name="motor3"><hardwareInterface>hardware_interface/PositionJointInterface</hardwareInterface><mechanicalReduction>100</mechanicalReduction></actuator></transmission><transmission name="tran4"><type>transmission_interface/SimpleTransmission</type><joint name="joint4"><hardwareInterface>hardware_interface/PositionJointInterface</hardwareInterface></joint><actuator name="motor4"><hardwareInterface>hardware_interface/PositionJointInterface</hardwareInterface><mechanicalReduction>100</mechanicalReduction></actuator></transmission><transmission name="tran5"><type>transmission_interface/SimpleTransmission</type><joint name="joint5"><hardwareInterface>hardware_interface/PositionJointInterface</hardwareInterface></joint><actuator name="motor5"><hardwareInterface>hardware_interface/PositionJointInterface</hardwareInterface><mechanicalReduction>100</mechanicalReduction></actuator></transmission><transmission name="tran6"><type>transmission_interface/SimpleTransmission</type><joint name="joint6"><hardwareInterface>hardware_interface/PositionJointInterface</hardwareInterface></joint><actuator name="motor6"><hardwareInterface>hardware_interface/PositionJointInterface</hardwareInterface><mechanicalReduction>100</mechanicalReduction></actuator></transmission><transmission name="tran7"><type>transmission_interface/SimpleTransmission</type><joint name="joint7"><hardwareInterface>hardware_interface/PositionJointInterface</hardwareInterface></joint><actuator name="motor7"><hardwareInterface>hardware_interface/PositionJointInterface</hardwareInterface><mechanicalReduction>100</mechanicalReduction></actuator></transmission><gazebo reference="link_base"><selfCollide>true</selfCollide></gazebo><gazebo reference="link1"><selfCollide>true</selfCollide></gazebo><gazebo reference="link2"><selfCollide>true</selfCollide></gazebo><gazebo reference="link3"><selfCollide>true</selfCollide></gazebo><gazebo reference="link4"><selfCollide>true</selfCollide></gazebo><gazebo reference="link5"><selfCollide>true</selfCollide></gazebo><gazebo reference="link6"><selfCollide>true</selfCollide></gazebo><gazebo reference="link7"><selfCollide>true</selfCollide></gazebo><link name="link_eef"/><joint name="joint_eef" type="fixed"><origin rpy="0 0 0" xyz="0 0 0"/><parent link="link7"/><child link="link_eef"/></joint><!-- Insert at the end of xarm_device_macro.xacro --></robot>', 
'robot_description_semantic': '<?xml version="1.0" ?><!-- =================================================================================== --><!-- |    This document was autogenerated by xacro from /home/hayden/cmu/kantor_lab/ros2_ws/install/xarm_moveit_config/share/xarm_moveit_config/srdf/xarm.srdf.xacro | --><!-- |    EDITING THIS FILE BY HAND IS NOT RECOMMENDED                                 | --><!-- =================================================================================== --><robot name="UF_ROBOT"><group name="xarm7"><joint name="world_joint"/><joint name="joint1"/><joint name="joint2"/><joint name="joint3"/><joint name="joint4"/><joint name="joint5"/><joint name="joint6"/><joint name="joint7"/><joint name="joint_eef"/></group><!-- GROUP STATES, Purpose, Define a named state for a particular group, in terms of joint values. This is useful to define states like \'folded arms\' --><group_state group="xarm7" name="home"><joint name="joint1" value="0"/><joint name="joint2" value="0"/><joint name="joint3" value="0"/><joint name="joint4" value="0"/><joint name="joint5" value="0"/><joint name="joint6" value="0"/><joint name="joint7" value="0"/></group_state><group_state group="xarm7" name="hold-up"><joint name="joint1" value="0"/><joint name="joint2" value="0"/><joint name="joint3" value="0"/><joint name="joint4" value="0"/><joint name="joint5" value="0"/><joint name="joint6" value="-1.5708"/><joint name="joint7" value="0"/></group_state><disable_collisions link1="link1" link2="link2" reason="Adjacent"/><disable_collisions link1="link1" link2="link3" reason="Never"/><disable_collisions link1="link1" link2="link4" reason="Never"/><disable_collisions link1="link1" link2="link_base" reason="Adjacent"/><disable_collisions link1="link2" link2="link3" reason="Adjacent"/><disable_collisions link1="link2" link2="link_base" reason="Never"/><disable_collisions link1="link3" link2="link4" reason="Adjacent"/><disable_collisions link1="link3" link2="link5" reason="Never"/><disable_collisions link1="link3" link2="link6" reason="Never"/><disable_collisions link1="link3" link2="link7" reason="Never"/><disable_collisions link1="link3" link2="link_base" reason="Never"/><disable_collisions link1="link4" link2="link5" reason="Adjacent"/><disable_collisions link1="link4" link2="link6" reason="Never"/><disable_collisions link1="link4" link2="link7" reason="Never"/><disable_collisions link1="link5" link2="link6" reason="Adjacent"/><disable_collisions link1="link5" link2="link7" reason="Never"/><disable_collisions link1="link6" link2="link7" reason="Adjacent"/><disable_collisions link1="link7" link2="link_eef" reason="Adjacent"/></robot>', 
'robot_description_kinematics': {'xarm7': {'kinematics_solver': 'kdl_kinematics_plugin/KDLKinematicsPlugin', 'kinematics_solver_search_resolution': 0.005, 'kinematics_solver_timeout': 0.005, 'kinematics_solver_attempts': 3}}, 
'planning_pipelines': ['ompl'], 
'default_planning_pipeline': 'ompl', 
'ompl': {'planning_plugin': 'ompl_interface/OMPLPlanner', 'start_state_max_bounds_error': 0.1, 'jiggle_fraction': 0.05, 'request_adapters': 'default_planner_request_adapters/AddTimeOptimalParameterization default_planner_request_adapters/ResolveConstraintFrames default_planner_request_adapters/FixWorkspaceBounds default_planner_request_adapters/FixStartStateBounds default_planner_request_adapters/FixStartStateCollision default_planner_request_adapters/FixStartStatePathConstraints', 
'xarm7': {'default_planner_config': 'RRTConnect', 'planner_configs': ['SBL', 'EST', 'LBKPIECE', 'BKPIECE', 'KPIECE', 'RRT', 'RRTConnect', 'RRTstar', 'TRRT', 'PRM', 'PRMstar', 'FMT', 'BFMT', 'PDST', 'STRIDE', 'BiTRRT', 'LBTRRT', 'BiEST', 'ProjEST', 'LazyPRM', 'LazyPRMstar', 'SPARS', 'SPARStwo']}, 
'planner_configs': {'SBL': {'type': 'geometric::SBL', 'range': 0.0}, 'EST': {'type': 'geometric::EST', 'range': 0.0, 'goal_bias': 0.05}, 'LBKPIECE': {'type': 'geometric::LBKPIECE', 'range': 0.0, 'border_fraction': 0.9, 'min_valid_path_fraction': 0.5}, 'BKPIECE': {'type': 'geometric::BKPIECE', 'range': 0.0, 'border_fraction': 0.9, 'failed_expansion_score_factor': 0.5, 'min_valid_path_fraction': 0.5}, 'KPIECE': {'type': 'geometric::KPIECE', 'range': 0.0, 'goal_bias': 0.05, 'border_fraction': 0.9, 'failed_expansion_score_factor': 0.5, 'min_valid_path_fraction': 0.5}, 'RRT': {'type': 'geometric::RRT', 'range': 0.0, 'goal_bias': 0.05}, 'RRTConnect': {'type': 'geometric::RRTConnect', 'range': 0.0}, 'RRTstar': {'type': 'geometric::RRTstar', 'range': 0.0, 'goal_bias': 0.05, 'delay_collision_checking': 1}, 'TRRT': {'type': 'geometric::TRRT', 'range': 0.0, 'goal_bias': 0.05, 'max_states_failed': 10, 'temp_change_factor': 2.0, 'min_temperature': '10e-10', 'init_temperature': '10e-6', 'frountier_threshold': 0.0, 'frountierNodeRatio': 0.1, 'k_constant': 0.0}, 'PRM': {'type': 'geometric::PRM', 'max_nearest_neighbors': 10}, 'PRMstar': {'type': 'geometric::PRMstar'}, 'FMT': {'type': 'geometric::FMT', 'num_samples': 1000, 'radius_multiplier': 1.1, 'nearest_k': 1, 'cache_cc': 1, 'heuristics': 0, 'extended_fmt': 1}, 'BFMT': {'type': 'geometric::BFMT', 'num_samples': 1000, 'radius_multiplier': 1.0, 'nearest_k': 1, 'balanced': 0, 'optimality': 1, 'heuristics': 1, 'cache_cc': 1, 'extended_fmt': 1}, 'PDST': {'type': 'geometric::PDST'}, 'STRIDE': {'type': 'geometric::STRIDE', 'range': 0.0, 'goal_bias': 0.05, 'use_projected_distance': 0, 'degree': 16, 'max_degree': 18, 'min_degree': 12, 'max_pts_per_leaf': 6, 'estimated_dimension': 0.0, 'min_valid_path_fraction': 0.2}, 'BiTRRT': {'type': 'geometric::BiTRRT', 'range': 0.0, 'temp_change_factor': 0.1, 'init_temperature': 100, 'frountier_threshold': 0.0, 'frountier_node_ratio': 0.1, 'cost_threshold': '1e300'}, 'LBTRRT': {'type': 'geometric::LBTRRT', 'range': 0.0, 'goal_bias': 0.05, 'epsilon': 0.4}, 'BiEST': {'type': 'geometric::BiEST', 'range': 0.0}, 'ProjEST': {'type': 'geometric::ProjEST', 'range': 0.0, 'goal_bias': 0.05}, 'LazyPRM': {'type': 'geometric::LazyPRM', 'range': 0.0}, 'LazyPRMstar': {'type': 'geometric::LazyPRMstar'}, 'SPARS': {'type': 'geometric::SPARS', 'stretch_factor': 3.0, 'sparse_delta_fraction': 0.25, 'dense_delta_fraction': 0.001, 'max_failures': 1000}, 'SPARStwo': {'type': 'geometric::SPARStwo', 'stretch_factor': 3.0, 'sparse_delta_fraction': 0.25, 'dense_delta_fraction': 0.001, 'max_failures': 5000}}},   
'moveit_manage_controllers': False,
  'moveit_controller_manager': 'moveit_simple_controller_manager/MoveItSimpleControllerManager',
  'moveit_simple_controller_manager': {
    'controller_names': ['xarm7_traj_controller'],
    'xarm7_traj_controller': {
      'action_ns': 'follow_joint_trajectory',
      'type': 'FollowJointTrajectory',
      'default': True,
      'joints': [
        'joint1', 'joint2', 'joint3', 'joint4',
        'joint5', 'joint6', 'joint7'
      ]
    }
  },
  'trajectory_execution': {
    'allowed_execution_duration_scaling': 1.2,
    'allowed_goal_duration_margin': 0.5,
    'allowed_start_tolerance': 0.01,
    'execution_duration_monitoring': False
  },
  'plan_execution': {
    'record_trajectory_state_frequency': 10.0
  },
  'publish_planning_scene': True,
  'publish_geometry_updates': True,
  'publish_state_updates': True,
  'publish_transforms_updates': True,
  'publish_robot_description': False,
  'publish_robot_description_semantic': False, 
  'robot_description_planning': {'joint_limits': {'joint1': {'has_velocity_limits': True, 'max_velocity': 2.14, 'has_acceleration_limits': True, 'max_acceleration': 10.0}, 'joint2': {'has_velocity_limits': True, 'max_velocity': 2.14, 'has_acceleration_limits': True, 'max_acceleration': 10.0}, 'joint3': {'has_velocity_limits': True, 'max_velocity': 2.14, 'has_acceleration_limits': True, 'max_acceleration': 10.0}, 'joint4': {'has_velocity_limits': True, 'max_velocity': 2.14, 'has_acceleration_limits': True, 'max_acceleration': 10.0}, 'joint5': {'has_velocity_limits': True, 'max_velocity': 2.14, 'has_acceleration_limits': True, 'max_acceleration': 10.0}, 'joint6': {'has_velocity_limits': True, 'max_velocity': 2.14, 'has_acceleration_limits': True, 'max_acceleration': 10.0}, 'joint7': {'has_velocity_limits': True, 'max_velocity': 2.14, 'has_acceleration_limits': True, 'max_acceleration': 10.0}}}}
